Workbook

Sheet Content Catalog
A1: # | B1: Title | C1: Approx Views | D1: Core Angle Bucket | E1: Specific Sub-Angle / Hook | F1: Near-Duplicate Flag
A2: 1 | B2: Jealous Envious People The Most Dangerous Truth: 14 Signs Someone Is Extremely Envious Of You! | C2: 8.8K | D2: Signs/Listicle - Envy | E2: 14-item behavioral checklist for toxic envy
A3: 2 | B3: Why The Most Dangerous Traits of Secret Envy Is Closer Than You Think — Carl Jung | C3: 2.4K | D3: Jungian Shadow | E3: Projection - why close peers turn resentful/critical
A4: 3 | B4: Why The Most Dangerous People Close to You Secretly Resent You — Carl Jung | C4: 1.5K | D4: Jungian Shadow | E4: Detaching from disguised resentment in inner circle | F4: Close to #10, #22
A5: 4 | B5: Carl Jung: NEVER Ignore These Dangerous Signs Someone Secretly Hates You | Carl Jung | C5: 1.1K | D5: Jungian Shadow - Secret Hate | E5: Early recognition of covert hostility | F5: Close to #42,43,45,46,47
A6: 5 | B6: The Only Thing Women Want – Machiavelli's Ruthless Truth About Female Nature | C6: 848 | D6: Outlier - Relationship Philosophy | E6: Classical-philosophy framing of relationship dynamics
A7: 6 | B7: Jealous People Always Say And Do These 14 Things! (Reverse Psychology) | C7: 846 | D7: Reverse Psychology - Verbal/Behavioral | E7: Handling backhanded compliments via reverse psych | F7: Close to #1, #23, #60
A8: 7 | B8: Secret Hate and Why The Most Dangerous People All Share This One Trait - Carl Jung | C8: 810 | D8: Jungian Shadow - Secret Hate | E8: Why insecure people project flaws onto others | F8: Close to #4
A9: 8 | B9: 8 Signs Someone Might Secretly Envy You | Reverse Psychology | C9: 727 | D9: Signs/Listicle - Envy | E9: Decoding subtle social undermining | F9: Close to #1, #27
A10: 9 | B10: The Most Dangerous Signs Someone Close to You Secretly Hates You: Carl Jung | C10: 614 | D10: Jungian Shadow - Secret Hate | E10: Spotting red flags before trusting with sensitive info | F10: Close to #4, #47
A11: 10 | B11: Why The Most Dangerous Jealousy Hides in People Close to You — Carl Jung | C11: 436 | D11: Jungian Shadow - Envy | E11: Envy within close circles / boundary-setting | F11: Close to #3, #65
A12: 11 | B12: Why The Most Dangerous People Hide Their Jealousy Right Next to You — Jung & Freud | C12: 343 | D12: Jungian/Freudian - Envy | E12: How close peers camouflage competitive jealousy | F12: Close to #10
A13: 12 | B13: Why The Most Dangerous Trait Hides in Plain Sight — Carl Jung | C13: 297 | D13: Jungian Shadow | E13: Covert antagonism disguised as humor/honest feedback
A14: 13 | B14: Toxic People Always Say These 7 Things — Catch Them Now | Reverse Psychology | C14: 279 | D14: Reverse Psychology - Verbal | E14: Decoding gaslighting/guilt-tripping phrases | F14: Close to #6
A15: 14 | B15: Why The Most Dangerous Signs of Jealousy Are Hidden — Carl Jung | C15: 253 | D15: Jungian Shadow - Envy | E15: Subtle passive-aggressive patterns before escalation | F15: Close to #37, #64
A16: 15 | B16: Why The Most Dangerous Jealousy Is Hidden in Plain Sight — Freud's Insight | C16: 249 | D16: Freudian - Envy | E16: Insecure people acting out when peer succeeds | F16: Close to #14, #37, #64
A17: 16 | B17: These Four Pillars of Immanuel Kant Will Make Old Age Happy | Philosophy and Psychology | C17: 202 | D17: Outlier - Aging/Philosophy | E17: Framework to overcome aging anxiety and regret
A18: 17 | B18: Carl Jung: Never Ignore The Most Dangerous Trait Shared by All Nice People — Carl Jung | C18: 198 | D18: Jungian Shadow - People-Pleasing | E18: People-pleasing and hidden resentment
A19: 18 | B19: People Who Imagine Fake Scenarios (the benefits no one tells you) | C19: 197 | D19: Outlier - Daydreaming | E19: Reframing maladaptive daydreaming as a tool
A20: 19 | B20: The Most Dangerous Sign in a Person — Plus 7 Toxic Traits and How to Outsmart Them | Carl Jung | C20: 180 | D20: Jungian Shadow + Reverse Psych | E20: Counter-strategies to neutralize manipulators
A21: 20 | B21: How to Make People Fear Disrespecting You! | A Motivational Speech on self-respect and boundaries | C21: 178 | D21: Respect/Boundaries - Disrespect | E21: Establishing unshakable self-worth and boundaries | F21: Close to #61, #75
A22: 21 | B22: Why The Most Dangerous Power Lies in Silent Detachment — Carl Jung | C22: N/A | D22: Jungian Shadow - Detachment | E22: Emotional detachment so others can't manipulate reactions
A23: 22 | B23: Why The Most Dangerous Enemies Hide Among Those You Trust — Carl Jung | C23: N/A | D23: Betrayal/Trust | E23: Spotting covert disloyalty in close circles | F23: Close to #38
A24: 23 | B24: Jealous People Always Say and Do These 8 Things! (Reverse Psychology) | C24: N/A | D24: Reverse Psychology - Verbal/Behavioral | E24: Identifying disguised envy / quick mental tools | F24: Close to #1, #6, #60
A25: 24 | B25: Jealous Envious People Always Say and Do These 3 Things (Reverse Psychology) | C25: N/A | D25: Reverse Psychology - Verbal/Behavioral | E25: Immediate verbal giveaways of jealousy | F25: Close to #1, #6, #23
A26: 25 | B26: How to Stop Getting Angry When Someone Reacts to You With Secret Hate! Stoicism | C26: N/A | D26: Stoicism - Composure | E26: Stoic mindset shifts for unprovoked animosity | F26: Close to #72
A27: 26 | B27: 14 Genius Ways to Outsmart Manipulators: Use Their Rejection to Your Advantage | Reverse Psychology | C27: N/A | D27: Manipulation Tactics | E27: Reframing rejection into leverage
A28: 27 | B28: Why The Most Dangerous People All Share These 14 Hidden Signs of Envy — Carl Jung | C28: N/A | D28: Signs/Listicle - Envy | E28: Deep-dive on micro-behaviors of covert envy | F28: Close to #1, #8
A29: 28 | B29: Never Ignore These Signs When Fed-Up Empaths React To Secret Hate | Carl Jung | C29: N/A | D29: Jungian Shadow - Empaths | E29: Empaths reaching their limit with negativity
A30: 29 | B30: Toxic Envy Exposed: These 8 Behaviors Never Lie | C30: N/A | D30: Signs/Listicle - Envy | E30: Undeniable behavioral patterns exposing resentment | F30: Close to #1, #27
A31: 30 | B31: Highly Likable People Do And Say these 4 Things | Reverse Psychology | C31: N/A | D31: Outlier - Likability/Charisma | E31: Psychological foundations of authentic charisma
A32: 31 | B32: Why The Most Dangerous People Use This One Jealousy Trick | C32: 291 | D32: Jealousy - Manipulation | E32: Subtle boundary erosion by competitive acquaintances
A33: 32 | B33: Jealous People Always Ask These 7 Questions (Don't Get Tricked Out Of Your Spot) | C33: 279 | D33: Jealousy - Verbal/Questions | E33: Probing questions designed to extract info / doubt
A34: 33 | B34: How To Spot Burnout or Laziness? Understanding the Difference! It's Easy, Actually! | C34: 278 | D34: Outlier - Burnout/Motivation | E34: Rest vs. lack of motivation distinction
A35: 34 | B35: How To Invest In Yourself! Taraji P Henson and A Bonus From Oprah! It's Easy, Actually! | C35: 268 | D35: Outlier - Self-Investment/Celebrity | E35: Overcoming imposter syndrome re: personal growth
A36: 35 | B36: Why The Most Dangerous Reaction To Disrespect Costs You — And How To Command Respect Instead | C36: 253 | D36: Respect/Boundaries - Commanding Respect | E36: High-status emotional regulation replacing reactive anger | F36: Close to #20, #75
A37: 36 | B37: Why The Most Dangerous People Hide Their Hate — And How To Spot Them | C37: 250 | D37: Jungian-adjacent - Hidden Hate | E37: Incongruencies between what covertly hostile people say/do | F37: Close to #4, #52
A38: 37 | B38: Why The Most Dangerous Envy Is What You Don't See Coming | C38: 245 | D38: Envy - Blindspot | E38: Spotting latent rivalry before gossip/sabotage | F38: Close to #14, #15, #64
A39: 38 | B39: Why The Most Dangerous Attacks Come From Those You Least Expect | C39: 244 | D39: Betrayal/Trust | E39: Emotional betrayal from allies; proximity breeds competition | F39: Close to #22
A40: 39 | B40: Why Pretending to Be Extroverted Is Ruining Your Relationships | C40: 231 | D40: Outlier - Introversion/Masking | E40: Stopping social masking for authentic communication
...

Sheet Bucket Summary
A1: Core Angle Bucket | B1: Video Count | C1: Status
A2: Betrayal/Trust | B2: =COUNTIF('Content Catalog'!D:D,"Betrayal/Trust") -> 3 | C2: Saturated - needs a genuinely new mechanism to add here
A3: Boundaries - Deflection | B3: =COUNTIF('Content Catalog'!D:D,"Boundaries - Deflection") -> 1 | C3: Saturated - needs a genuinely new mechanism to add here
A4: Boundaries - Energy Management | B4: =COUNTIF('Content Catalog'!D:D,"Boundaries - Energy Management") -> 1 | C4: Saturated - needs a genuinely new mechanism to add here
A5: Envy - Blindspot | B5: =COUNTIF('Content Catalog'!D:D,"Envy - Blindspot") -> 2 | C5: Saturated - needs a genuinely new mechanism to add here
A6: Envy - Reframe | B6: =COUNTIF('Content Catalog'!D:D,"Envy - Reframe") -> 1 | C6: Saturated - needs a genuinely new mechanism to add here
A7: Fake Friends | B7: =COUNTIF('Content Catalog'!D:D,"Fake Friends") -> 2 | C7: Saturated - needs a genuinely new mechanism to add here
A8: Fake Friends/Friendship Fallout | B8: =COUNTIF('Content Catalog'!D:D,"Fake Friends/Friendship Fallout") -> 2 | C8: Saturated - needs a genuinely new mechanism to add here
A9: Freudian - Envy | B9: =COUNTIF('Content Catalog'!D:D,"Freudian - Envy") -> 1 | C9: Saturated - needs a genuinely new mechanism to add here
A10: Jealousy - Manipulation | B10: =COUNTIF('Content Catalog'!D:D,"Jealousy - Manipulation") -> 1 | C10: Saturated - needs a genuinely new mechanism to add here
A11: Jealousy - Subtle Signs | B11: =COUNTIF('Content Catalog'!D:D,"Jealousy - Subtle Signs") -> 1 | C11: Saturated - needs a genuinely new mechanism to add here
A12: Jealousy - Validation | B12: =COUNTIF('Content Catalog'!D:D,"Jealousy - Validation") -> 1 | C12: Saturated - needs a genuinely new mechanism to add here
A13: Jealousy - Verbal Cues | B13: =COUNTIF('Content Catalog'!D:D,"Jealousy - Verbal Cues") -> 2 | C13: Saturated - needs a genuinely new mechanism to add here
A14: Jealousy - Verbal Putdowns | B14: =COUNTIF('Content Catalog'!D:D,"Jealousy - Verbal Putdowns") -> 1 | C14: Saturated - needs a genuinely new mechanism to add here
A15: Jealousy - Verbal/Questions | B15: =COUNTIF('Content Catalog'!D:D,"Jealousy - Verbal/Questions") -> 1 | C15: Saturated - needs a genuinely new mechanism to add here
A16: Jealousy - Verbal/Trust | B16: =COUNTIF('Content Catalog'!D:D,"Jealousy - Verbal/Trust") -> 1 | C16: Saturated - needs a genuinely new mechanism to add here
A17: Jealousy/Reverse Psych - Secret Hate | B17: =COUNTIF('Content Catalog'!D:D,"Jealousy/Reverse Psych - Secret Hate") -> 1 | C17: Saturated - needs a genuinely new mechanism to add here
A18: Jungian Shadow | B18: =COUNTIF('Content Catalog'!D:D,"Jungian Shadow") -> 3 | C18: Saturated - needs a genuinely new mechanism to add here
A19: Jungian Shadow + Reverse Psych | B19: =COUNTIF('Content Catalog'!D:D,"Jungian Shadow + Reverse Psych") -> 1 | C19: Saturated - needs a genuinely new mechanism to add here
A20: Jungian Shadow - Detachment | B20: =COUNTIF('Content Catalog'!D:D,"Jungian Shadow - Detachment") -> 1 | C20: Saturated - needs a genuinely new mechanism to add here
A21: Jungian Shadow - Empaths | B21: =COUNTIF('Content Catalog'!D:D,"Jungian Shadow - Empaths") -> 1 | C21: Saturated - needs a genuinely new mechanism to add here
A22: Jungian Shadow - Envy | B22: =COUNTIF('Content Catalog'!D:D,"Jungian Shadow - Envy") -> 2 | C22: Saturated - needs a genuinely new mechanism to add here
A23: Jungian Shadow - People-Pleasing | B23: =COUNTIF('Content Catalog'!D:D,"Jungian Shadow - People-Pleasing") -> 1 | C23: Saturated - needs a genuinely new mechanism to add here
A24: Jungian Shadow - Secret Hate | B24: =COUNTIF('Content Catalog'!D:D,"Jungian Shadow - Secret Hate") -> 7 | C24: Saturated - needs a genuinely new mechanism to add here
A25: Jungian-adjacent - Hidden Hate | B25: =COUNTIF('Content Catalog'!D:D,"Jungian-adjacent - Hidden Hate") -> 1 | C25: Saturated - needs a genuinely new mechanism to add here
A26: Jungian-adjacent - Secret Hate | B26: =COUNTIF('Content Catalog'!D:D,"Jungian-adjacent - Secret Hate") -> 1 | C26: Saturated - needs a genuinely new mechanism to add here
A27: Jungian/Freudian - Envy | B27: =COUNTIF('Content Catalog'!D:D,"Jungian/Freudian - Envy") -> 1 | C27: Saturated - needs a genuinely new mechanism to add here
A28: Manipulation Tactics | B28: =COUNTIF('Content Catalog'!D:D,"Manipulation Tactics") -> 1 | C28: Saturated - needs a genuinely new mechanism to add here
A29: Manipulation Tactics - Gaslighting | B29: =COUNTIF('Content Catalog'!D:D,"Manipulation Tactics - Gaslighting") -> 1 | C29: Saturated - needs a genuinely new mechanism to add here
A30: Outlier - Aging/Philosophy | B30: =COUNTIF('Content Catalog'!D:D,"Outlier - Aging/Philosophy") -> 1 | C30: Saturated - needs a genuinely new mechanism to add here
A31: Outlier - Ambition/Burnout | B31: =COUNTIF('Content Catalog'!D:D,"Outlier - Ambition/Burnout") -> 1 | C31: Saturated - needs a genuinely new mechanism to add here
A32: Outlier - Burnout/Motivation | B32: =COUNTIF('Content Catalog'!D:D,"Outlier - Burnout/Motivation") -> 1 | C32: Saturated - needs a genuinely new mechanism to add here
A33: Outlier - Daydreaming | B33: =COUNTIF('Content Catalog'!D:D,"Outlier - Daydreaming") -> 1 | C33: Saturated - needs a genuinely new mechanism to add here
A34: Outlier - Dislike/Boundaries | B34: =COUNTIF('Content Catalog'!D:D,"Outlier - Dislike/Boundaries") -> 1 | C34: Saturated - needs a genuinely new mechanism to add here
A35: Outlier - Habits/Self-Improvement | B35: =COUNTIF('Content Catalog'!D:D,"Outlier - Habits/Self-Improvement") -> 1 | C35: Saturated - needs a genuinely new mechanism to add here
A36: Outlier - Healing/Positive | B36: =COUNTIF('Content Catalog'!D:D,"Outlier - Healing/Positive") -> 1 | C36: Saturated - needs a genuinely new mechanism to add here
A37: Outlier - Introversion/Masking | B37: =COUNTIF('Content Catalog'!D:D,"Outlier - Introversion/Masking") -> 1 | C37: Saturated - needs a genuinely new mechanism to add here
A38: Outlier - Likability/Charisma | B38: =COUNTIF('Content Catalog'!D:D,"Outlier - Likability/Charisma") -> 1 | C38: Saturated - needs a genuinely new mechanism to add here
A39: Outlier - Relationship Philosophy | B39: =COUNTIF('Content Catalog'!D:D,"Outlier - Relationship Philosophy") -> 1 | C39: Saturated - needs a genuinely new mechanism to add here
A40: Outlier - Rumination/Past | B40: =COUNTIF('Content Catalog'!D:D,"Outlier - Rumination/Past") -> 1 | C40: Saturated - needs a genuinely new mechanism to add here
...

Sheet Pre-Publish Checklist
A1: Cannibalization Audit — Run Before Locking Any New Title
B3: Step 1 — Identify the bucket
B4: ☐ Which Core Angle Bucket (see 'Bucket Summary' tab) does the new idea fall into? If it doesn't fit any existing bucket, that's a strong green light — it's genuinely new ground.
B5: ☐ Check the bucket's count. 3+ videos already in that bucket means the next one needs a real reason to exist, not just a new adjective in the title.
B6: Step 2 — Check the specific mechanism, not just the topic
B7: ☐ Open the 'Content Catalog' tab, filter to that bucket, and read the 'Specific Sub-Angle / Hook' column. Does any existing video already use the exact same mechanism (same behavior, same reveal, same resolution)?
B8: ☐ Same topic + different mechanism = OK to publish. Same topic + same mechanism + different adjective in the title = cannibalization risk, even if the exact keyword phrase looks different.
B9: Step 3 — Check against the 'Near-Duplicate Flag' column
B10: ☐ Rows already flagged as close to each other show you what the channel's actual repeat pattern looks like (same secret-hate/Jungian angle repeated 6+ times, for example). Don't add a 7th without a new mechanism.
B11: ☐ If the new idea would flag against 2+ existing rows, stop and sharpen the angle before building the thumbnail or script.
B12: Step 4 — Check search intent, not just title wording
B13: ☐ Would a viewer searching for this new title also be satisfied by clicking an existing video? If yes, that's search-intent overlap even with zero shared words in the title — this is the same mechanic that caused the Studio-flagged cannibalization on the signs-of-jealousy cluster.
B14: ☐ VidIQ's keyword target for the new idea should be a genuinely different search term from any keyword already heavily used in that bucket (see Bucket Summary), not just a different phrasing of the same intent.
... B19: ☐ Low view counts on most existing videos don't exempt a topic from this check — a video with 100 views still occupies that search intent and can still split impressions with a new upload.
